<sdf version='1.11'>
  <model name='robot'>
    <link name='base_link'>
      <inertial>
        <pose>0.065000000000000002 0 0.1125 0 0 0</pose>
        <mass>0.59999999999999998</mass>
        <inertia>
          <ixx>0.0052562499999999979</ixx>
          <ixy>0</ixy>
          <ixz>0.00056250000000000093</ixz>
          <iyy>0.0059312499999999964</iyy>
          <iyz>0</iyz>
          <izz>0.0082749999999999976</izz>
        </inertia>
      </inertial>
      <collision name='base_link_fixed_joint_lump__chassis_collision'>
        <pose>0.049999999999999989 0 0.125 0 0 0</pose>
        <geometry>
          <box>
            <size>0.29999999999999999 0.29999999999999999 0.14999999999999999</size>
          </box>
        </geometry>
      </collision>
      <collision name='base_link_fixed_joint_lump__caster_wheel_collision_1'>
        <pose>0.14000000000000001 0 0.050000000000000003 0 0 0</pose>
        <geometry>
          <sphere>
            <radius>0.050000000000000003</radius>
          </sphere>
        </geometry>
      </collision>
      <visual name='base_link_fixed_joint_lump__chassis_visual'>
        <pose>0.049999999999999989 0 0.125 0 0 0</pose>
        <geometry>
          <box>
            <size>0.29999999999999999 0.29999999999999999 0.14999999999999999</size>
          </box>
        </geometry>
        <material>
          <diffuse>1 1 1 1</diffuse>
          <ambient>1 1 1 1</ambient>
        </material>
      </visual>
      <visual name='base_link_fixed_joint_lump__caster_wheel_visual_1'>
        <pose>0.14000000000000001 0 0.050000000000000003 0 0 0</pose>
        <geometry>
          <sphere>
            <radius>0.050000000000000003</radius>
          </sphere>
        </geometry>
        <material>
          <diffuse>0 0 0 1</diffuse>
          <ambient>0 0 0 1</ambient>
        </material>
      </visual>
    </link>
    <joint name='left_wheel_joint' type='revolute'>
      <pose relative_to='base_link'>0 0.17499999999999999 0.050000000000000003 -1.5707963267948959 0 0</pose>
      <parent>base_link</parent>
      <child>left_wheel</child>
      <axis>
        <xyz>0 0 1</xyz>
        <limit>
          <lower>-inf</lower>
          <upper>inf</upper>
        </limit>
        <dynamics>
          <spring_reference>0</spring_reference>
          <spring_stiffness>0</spring_stiffness>
        </dynamics>
      </axis>
    </joint>
    <link name='left_wheel'>
      <pose relative_to='left_wheel_joint'>0 0 0 0 0 0</pose>
      <inertial>
        <pose>0 0 0 0 0 0</pose>
        <mass>0.10000000000000001</mass>
        <inertia>
          <ixx>8.3333333333333344e-05</ixx>
          <ixy>0</ixy>
          <ixz>0</ixz>
          <iyy>8.3333333333333344e-05</iyy>
          <iyz>0</iyz>
          <izz>0.000125</izz>
        </inertia>
      </inertial>
      <collision name='left_wheel_collision'>
        <pose>0 0 0 0 0 0</pose>
        <geometry>
          <cylinder>
            <length>0.040000000000000001</length>
            <radius>0.050000000000000003</radius>
          </cylinder>
        </geometry>
      </collision>
      <visual name='left_wheel_visual'>
        <pose>0 0 0 0 0 0</pose>
        <geometry>
          <cylinder>
            <length>0.040000000000000001</length>
            <radius>0.050000000000000003</radius>
          </cylinder>
        </geometry>
        <material>
          <diffuse>0.25 0.25 1 1</diffuse>
          <ambient>0.25 0.25 1 1</ambient>
        </material>
      </visual>
    </link>
    <joint name='right_wheel_joint' type='revolute'>
      <pose relative_to='base_link'>0 -0.17499999999999999 0.050000000000000003 1.5707963267948959 0 0</pose>
      <parent>base_link</parent>
      <child>right_wheel</child>
      <axis>
        <xyz>0 0 -1</xyz>
        <limit>
          <lower>-inf</lower>
          <upper>inf</upper>
        </limit>
        <dynamics>
          <spring_reference>0</spring_reference>
          <spring_stiffness>0</spring_stiffness>
        </dynamics>
      </axis>
    </joint>
    <link name='right_wheel'>
      <pose relative_to='right_wheel_joint'>0 0 0 0 0 0</pose>
      <inertial>
        <pose>0 0 0 0 0 0</pose>
        <mass>0.10000000000000001</mass>
        <inertia>
          <ixx>8.3333333333333344e-05</ixx>
          <ixy>0</ixy>
          <ixz>0</ixz>
          <iyy>8.3333333333333344e-05</iyy>
          <iyz>0</iyz>
          <izz>0.000125</izz>
        </inertia>
      </inertial>
      <collision name='right_wheel_collision'>
        <pose>0 0 0 0 0 0</pose>
        <geometry>
          <cylinder>
            <length>0.040000000000000001</length>
            <radius>0.050000000000000003</radius>
          </cylinder>
        </geometry>
      </collision>
      <visual name='right_wheel_visual'>
        <pose>0 0 0 0 0 0</pose>
        <geometry>
          <cylinder>
            <length>0.040000000000000001</length>
            <radius>0.050000000000000003</radius>
          </cylinder>
        </geometry>
        <material>
          <diffuse>0.25 0.25 1 1</diffuse>
          <ambient>0.25 0.25 1 1</ambient>
        </material>
      </visual>
    </link>
    <frame name='caster_wheel_joint' attached_to='chassis'>
      <pose>0.23999999999999999 0 0 0 0 0</pose>
    </frame>
    <frame name='caster_wheel' attached_to='caster_wheel_joint'>
      <pose>0 0 0 0 0 0</pose>
    </frame>
    <frame name='chassis_joint' attached_to='base_link'>
      <pose>-0.10000000000000001 0 0.050000000000000003 0 0 0</pose>
    </frame>
    <frame name='chassis' attached_to='chassis_joint'>
      <pose>0 0 0 0 0 0</pose>
    </frame>
  </model>
</sdf>
