<?xml version="1.0" ?>
<!-- =================================================================================== -->
<!-- |    This document was autogenerated by xacro from robot.urdf.xacro               | -->
<!-- |    EDITING THIS FILE BY HAND IS NOT RECOMMENDED                                 | -->
<!-- =================================================================================== -->
<robot name="robot">
  <!-- Specify some standard inertial calculations https://en.wikipedia.org/wiki/List_of_moments_of_inertia -->
  <!-- These make use of xacro's mathematical functionality -->
  <material name="white">
    <color rgba="1 1 1 1"/>
  </material>
  <material name="orange">
    <color rgba="1 0.3 0.1 1"/>
  </material>
  <material name="blue">
    <color rgba="0.2 0.2 1 1"/>
  </material>
  <material name="black">
    <color rgba="0 0 0 1"/>
  </material>
  <link name="base_link">
    </link>
  <joint name="chassis_joint" type="fixed">
    <parent link="base_link"/>
    <child link="chassis"/>
    <origin xyz="-0.1 0 0.05"/>
  </joint>
  <link name="chassis">
    <visual>
      <origin rpy="0 0 0" xyz="0.15 0 0.075"/>
      <geometry>
        <box size="0.3 0.3 0.15"/>
      </geometry>
      <material name="white"/>
    </visual>
    <collision>
      <origin rpy="0 0 0" xyz="0.15 0 0.075"/>
      <geometry>
        <box size="0.3 0.3 0.15"/>
      </geometry>
    </collision>
    <inertial>
      <origin rpy="0 0 0" xyz="0.15 0 0.075"/>
      <mass value="0.5"/>
      <inertia ixx="0.004687499999999999" ixy="0.0" ixz="0.0" iyy="0.004687499999999999" iyz="0.0" izz="0.0075"/>
    </inertial>
  </link>
  <!-- LEFT WHEEL -->
  <joint name="left_wheel_joint" type="continuous">
    <parent link="base_link"/>
    <child link="left_wheel"/>
    <origin rpy="-1.5707963267948966 0 0" xyz="0 0.175 0.05"/>
    <axis xyz="0 0 1"/>
  </joint>
  <link name="left_wheel">
    <visual>
      <geometry>
        <cylinder length="0.04" radius="0.05"/>
      </geometry>
      <material name="blue"/>
    </visual>
    <collision>
      <geometry>
        <cylinder length="0.04" radius="0.05"/>
      </geometry>
      <material name="blue"/>
    </collision>
    <inertial>
      <origin rpy="0 0 0" xyz="0 0 0"/>
      <mass value="0.1"/>
      <inertia ixx="8.333333333333334e-05" ixy="0.0" ixz="0.0" iyy="8.333333333333334e-05" iyz="0.0" izz="0.00012500000000000003"/>
    </inertial>
  </link>
  <!-- RIGHT WHEEL -->
  <joint name="right_wheel_joint" type="continuous">
    <parent link="base_link"/>
    <child link="right_wheel"/>
    <origin rpy="1.5707963267948966 0 0" xyz="0 -0.175 0.05"/>
    <axis xyz="0 0 -1"/>
  </joint>
  <link name="right_wheel">
    <visual>
      <geometry>
        <cylinder length="0.04" radius="0.05"/>
      </geometry>
      <material name="blue"/>
    </visual>
    <collision>
      <geometry>
        <cylinder length="0.04" radius="0.05"/>
      </geometry>
      <material name="blue"/>
    </collision>
    <inertial>
      <origin rpy="0 0 0" xyz="0 0 0"/>
      <mass value="0.1"/>
      <inertia ixx="8.333333333333334e-05" ixy="0.0" ixz="0.0" iyy="8.333333333333334e-05" iyz="0.0" izz="0.00012500000000000003"/>
    </inertial>
  </link>
  <!-- CASTER WHEEL -->
  <joint name="caster_wheel_joint" type="fixed">
    <parent link="chassis"/>
    <child link="caster_wheel"/>
    <origin rpy="0 0 0" xyz="0.24 0 0"/>
  </joint>
  <link name="caster_wheel">
    <visual>
      <geometry>
        <sphere radius="0.05"/>
      </geometry>
      <material name="black"/>
      <gazebo reference="caster_wheel">
        <material>Gazebo/Black</material>
        <mu1 value="0.001"/>
        <mu2 value="0.001"/>
      </gazebo>
    </visual>
    <collision>
      <geometry>
        <sphere radius="0.05"/>
      </geometry>
      <material name="black"/>
    </collision>
    <inertial>
      <origin rpy="0 0 0" xyz="0 0 0"/>
      <mass value="0.1"/>
      <inertia ixx="0.00010000000000000005" ixy="0.0" ixz="0.0" iyy="0.00010000000000000005" iyz="0.0" izz="0.00010000000000000005"/>
    </inertial>
  </link>
  <!-- COLLISION INFORMATION -->
</robot>
